<?xml version="1.0" ?>
<!-- =================================================================================== -->
<!-- |    This document was autogenerated by xacro from abb_crb15000_support/urdf/crb15000_5_95.xacro | -->
<!-- |    EDITING THIS FILE BY HAND IS NOT RECOMMENDED                                 | -->
<!-- =================================================================================== -->
<robot name="abb_crb15000_5_95">
  <!-- Conversion were obtained from http://www.e-paint.co.uk/Lab_values.asp
       unless otherwise stated. -->
  <!-- link list -->
  <link name="robotA_base_link">
    <collision>
      <geometry>
        <mesh filename="meshes/crb15000_5_95/collision/base_link.stl"/>
      </geometry>
    </collision>
    <visual>
      <geometry>
        <mesh filename="meshes/crb15000_5_95/visual/base_link.stl"/>
      </geometry>
      <material name="">
        <color rgba="0.3450980 0.3647059 0.3686275 1"/>
      </material>
    </visual>
  </link>
  <link name="robotA_link_1">
    <collision>
      <geometry>
        <mesh filename="meshes/crb15000_5_95/collision/link_1.stl"/>
      </geometry>
    </collision>
    <visual>
      <geometry>
        <mesh filename="meshes/crb15000_5_95/visual/link_1.stl"/>
      </geometry>
      <material name="">
        <color rgba="0.3450980 0.3647059 0.3686275 1"/>
      </material>
    </visual>
  </link>
  <link name="robotA_link_2">
    <collision>
      <geometry>
        <mesh filename="meshes/crb15000_5_95/collision/link_2.stl"/>
      </geometry>
    </collision>
    <visual>
      <geometry>
        <mesh filename="meshes/crb15000_5_95/visual/link_2.stl"/>
      </geometry>
      <material name="">
        <color rgba="0.3450980 0.3647059 0.3686275 1"/>
      </material>
    </visual>
  </link>
  <link name="robotA_link_3">
    <collision>
      <geometry>
        <mesh filename="meshes/crb15000_5_95/collision/link_3.stl"/>
      </geometry>
    </collision>
    <visual>
      <geometry>
        <mesh filename="meshes/crb15000_5_95/visual/link_3.stl"/>
      </geometry>
      <material name="">
        <color rgba="0.3450980 0.3647059 0.3686275 1"/>
      </material>
    </visual>
  </link>
  <link name="robotA_link_4">
    <collision>
      <geometry>
        <mesh filename="meshes/crb15000_5_95/collision/link_4.stl"/>
      </geometry>
    </collision>
    <visual>
      <geometry>
        <mesh filename="meshes/crb15000_5_95/visual/link_4.stl"/>
      </geometry>
      <material name="">
        <color rgba="0.7725490 0.7803922 0.7686275 1"/>
      </material>
    </visual>
  </link>
  <link name="robotA_link_5">
    <collision>
      <geometry>
        <mesh filename="meshes/crb15000_5_95/collision/link_5.stl"/>
      </geometry>
    </collision>
    <visual>
      <geometry>
        <mesh filename="meshes/crb15000_5_95/visual/link_5.stl"/>
      </geometry>
      <material name="">
        <color rgba="0.7725490 0.7803922 0.7686275 1"/>
      </material>
    </visual>
  </link>
  <link name="robotA_link_6">
    <collision>
      <geometry>
        <mesh filename="meshes/crb15000_5_95/collision/link_6_2.stl"/>
      </geometry>
    </collision>
    <visual>
      <geometry>
        <mesh filename="meshes/crb15000_5_95/visual/link_6_2.stl"/>
      </geometry>
      <material name="">
        <color rgba="0.8392157 0.8352941 0.7921569 1"/>
      </material>
    </visual>
  </link>
  <!-- end of link list -->
  <!-- joint list -->
  <joint name="robotA_joint_1" type="revolute">
    <origin rpy="0 0 0" xyz="0 0 0.265"/>
    <axis xyz="0 0 1"/>
    <parent link="robotA_base_link"/>
    <child link="robotA_link_1"/>
    <limit effort="0" lower="-3.141592653589793" upper="3.141592653589793" velocity="2.181661564992912"/>
  </joint>
  <joint name="robotA_joint_2" type="revolute">
    <origin rpy="0 0 0" xyz="0 0 0"/>
    <axis xyz="0 1 0"/>
    <parent link="robotA_link_1"/>
    <child link="robotA_link_2"/>
    <limit effort="0" lower="-3.141592653589793" upper="3.141592653589793" velocity="2.181661564992912"/>
  </joint>
  <joint name="robotA_joint_3" type="revolute">
    <origin rpy="0 0 0" xyz="0 0 0.444"/>
    <axis xyz="0 1 0"/>
    <parent link="robotA_link_2"/>
    <child link="robotA_link_3"/>
    <limit effort="0" lower="-3.9269908169872414" upper="1.4835298641951802" velocity="2.443460952792061"/>
  </joint>
  <joint name="robotA_joint_4" type="revolute">
    <origin rpy="0 0 0" xyz="0 0 0.110"/>
    <axis xyz="1 0 0"/>
    <parent link="robotA_link_3"/>
    <child link="robotA_link_4"/>
    <limit effort="0" lower="-3.141592653589793" upper="3.141592653589793" velocity="3.490658503988659"/>
  </joint>
  <joint name="robotA_joint_5" type="revolute">
    <origin rpy="0 0 0" xyz="0.470 0 0"/>
    <axis xyz="0 1 0"/>
    <parent link="robotA_link_4"/>
    <child link="robotA_link_5"/>
    <limit effort="0" lower="-3.141592653589793" upper="3.141592653589793" velocity="3.490658503988659"/>
  </joint>
  <joint name="robotA_joint_6" type="revolute">
    <origin rpy="0 0 0" xyz="0.101 0 0.080"/>
    <axis xyz="1 0 0"/>
    <parent link="robotA_link_5"/>
    <child link="robotA_link_6"/>
    <limit effort="0" lower="-3.141592653589793" upper="3.141592653589793" velocity="3.490658503988659"/>
  </joint>
  <!-- end of joint list -->
  <!-- ROS-Industrial 'base' frame: base_link to ABB World Coordinates transform -->
  <link name="robotA_base"/>
  <joint name="robotA_base_link-base" type="fixed">
    <origin rpy="0 0 0" xyz="0 0 0"/>
    <parent link="robotA_base_link"/>
    <child link="robotA_base"/>
  </joint>
  <!-- ROS-Industrial 'flange' frame: attachment point for EEF models -->
  <link name="robotA_flange"/>
  <joint name="robotA_joint_6-flange" type="fixed">
    <origin rpy="0 0 0" xyz="0 0 0"/>
    <parent link="robotA_link_6"/>
    <child link="robotA_flange"/>
  </joint>
  <!-- ROS-Industrial 'tool0' frame: all-zeros tool frame -->
  <link name="robotA_tool0"/>
  <joint name="robotA_flange-tool0" type="fixed">
    <origin rpy="0 1.5707963267948966 0" xyz="0 0 0"/>
    <parent link="robotA_flange"/>
    <child link="robotA_tool0"/>
  </joint>

  <link name="robotB_base_link">
    <collision>
      <geometry>
        <mesh filename="meshes/crb15000_5_95/collision/base_link.stl"/>
      </geometry>
    </collision>
    <visual>
      <geometry>
        <mesh filename="meshes/crb15000_5_95/visual/base_link.stl"/>
      </geometry>
      <material name="">
        <color rgba="0.3450980 0.3647059 0.3686275 1"/>
      </material>
    </visual>
  </link>
  <link name="robotB_link_1">
    <collision>
      <geometry>
        <mesh filename="meshes/crb15000_5_95/collision/link_1.stl"/>
      </geometry>
    </collision>
    <visual>
      <geometry>
        <mesh filename="meshes/crb15000_5_95/visual/link_1.stl"/>
      </geometry>
      <material name="">
        <color rgba="0.3450980 0.3647059 0.3686275 1"/>
      </material>
    </visual>
  </link>
  <link name="robotB_link_2">
    <collision>
      <geometry>
        <mesh filename="meshes/crb15000_5_95/collision/link_2.stl"/>
      </geometry>
    </collision>
    <visual>
      <geometry>
        <mesh filename="meshes/crb15000_5_95/visual/link_2.stl"/>
      </geometry>
      <material name="">
        <color rgba="0.3450980 0.3647059 0.3686275 1"/>
      </material>
    </visual>
  </link>
  <link name="robotB_link_3">
    <collision>
      <geometry>
        <mesh filename="meshes/crb15000_5_95/collision/link_3.stl"/>
      </geometry>
    </collision>
    <visual>
      <geometry>
        <mesh filename="meshes/crb15000_5_95/visual/link_3.stl"/>
      </geometry>
      <material name="">
        <color rgba="0.3450980 0.3647059 0.3686275 1"/>
      </material>
    </visual>
  </link>
  <link name="robotB_link_4">
    <collision>
      <geometry>
        <mesh filename="meshes/crb15000_5_95/collision/link_4.stl"/>
      </geometry>
    </collision>
    <visual>
      <geometry>
        <mesh filename="meshes/crb15000_5_95/visual/link_4.stl"/>
      </geometry>
      <material name="">
        <color rgba="0.7725490 0.7803922 0.7686275 1"/>
      </material>
    </visual>
  </link>
  <link name="robotB_link_5">
    <collision>
      <geometry>
        <mesh filename="meshes/crb15000_5_95/collision/link_5.stl"/>
      </geometry>
    </collision>
    <visual>
      <geometry>
        <mesh filename="meshes/crb15000_5_95/visual/link_5.stl"/>
      </geometry>
      <material name="">
        <color rgba="0.7725490 0.7803922 0.7686275 1"/>
      </material>
    </visual>
  </link>
  <link name="robotB_link_6">
    <collision>
      <geometry>
        <mesh filename="meshes/crb15000_5_95/collision/link_6_2.stl"/>
      </geometry>
    </collision>
    <visual>
      <geometry>
        <mesh filename="meshes/crb15000_5_95/visual/link_6_2.stl"/>
      </geometry>
      <material name="">
        <color rgba="0.8392157 0.8352941 0.7921569 1"/>
      </material>
    </visual>
  </link>
  <!-- end of link list -->
  <!-- joint list -->
  <joint name="robotB_joint_1" type="revolute">
    <origin rpy="0 0 0" xyz="0 0 0.265"/>
    <axis xyz="0 0 1"/>
    <parent link="robotB_base_link"/>
    <child link="robotB_link_1"/>
    <limit effort="0" lower="-3.141592653589793" upper="3.141592653589793" velocity="2.181661564992912"/>
  </joint>
  <joint name="robotB_joint_2" type="revolute">
    <origin rpy="0 0 0" xyz="0 0 0"/>
    <axis xyz="0 1 0"/>
    <parent link="robotB_link_1"/>
    <child link="robotB_link_2"/>
    <limit effort="0" lower="-3.141592653589793" upper="3.141592653589793" velocity="2.181661564992912"/>
  </joint>
  <joint name="robotB_joint_3" type="revolute">
    <origin rpy="0 0 0" xyz="0 0 0.444"/>
    <axis xyz="0 1 0"/>
    <parent link="robotB_link_2"/>
    <child link="robotB_link_3"/>
    <limit effort="0" lower="-3.9269908169872414" upper="1.4835298641951802" velocity="2.443460952792061"/>
  </joint>
  <joint name="robotB_joint_4" type="revolute">
    <origin rpy="0 0 0" xyz="0 0 0.110"/>
    <axis xyz="1 0 0"/>
    <parent link="robotB_link_3"/>
    <child link="robotB_link_4"/>
    <limit effort="0" lower="-3.141592653589793" upper="3.141592653589793" velocity="3.490658503988659"/>
  </joint>
  <joint name="robotB_joint_5" type="revolute">
    <origin rpy="0 0 0" xyz="0.470 0 0"/>
    <axis xyz="0 1 0"/>
    <parent link="robotB_link_4"/>
    <child link="robotB_link_5"/>
    <limit effort="0" lower="-3.141592653589793" upper="3.141592653589793" velocity="3.490658503988659"/>
  </joint>
  <joint name="robotB_joint_6" type="revolute">
    <origin rpy="0 0 0" xyz="0.101 0 0.080"/>
    <axis xyz="1 0 0"/>
    <parent link="robotB_link_5"/>
    <child link="robotB_link_6"/>
    <limit effort="0" lower="-3.141592653589793" upper="3.141592653589793" velocity="3.490658503988659"/>
  </joint>
  <!-- end of joint list -->
  <!-- ROS-Industrial 'base' frame: base_link to ABB World Coordinates transform -->
  <link name="robotB_base"/>
  <joint name="robotB_base_link-base" type="fixed">
    <origin rpy="0 0 0" xyz="0 0 0"/>
    <parent link="robotB_base_link"/>
    <child link="robotB_base"/>
  </joint>
  <!-- ROS-Industrial 'flange' frame: attachment point for EEF models -->
  <link name="robotB_flange"/>
  <joint name="robotB_joint_6-flange" type="fixed">
    <origin rpy="0 0 0" xyz="0 0 0"/>
    <parent link="robotB_link_6"/>
    <child link="robotB_flange"/>
  </joint>
  <!-- ROS-Industrial 'tool0' frame: all-zeros tool frame -->
  <link name="robotB_tool0"/>
  <joint name="robotB_flange-tool0" type="fixed">
    <origin rpy="0 1.5707963267948966 0" xyz="0 0 0"/>
    <parent link="robotB_flange"/>
    <child link="robotB_tool0"/>
  </joint>

  <link name="world"/>
  <joint name="robotA_joint" type="fixed">
    <parent link="world"/>
    <child link="robotA_base_link"/>
    <origin rpy="0.0 0 0" xyz="0.0 0 0"/>
  </joint>
  <joint name="robotB_joint" type="fixed">
    <parent link="world"/>
    <child link="robotB_base_link"/>
    <origin rpy="0.00185601007 0.00214706491 3.13677599" xyz="2.36007471 -0.0359336150	0.000872916796"/>
  </joint>
</robot>
