<?xml version="1.0" ?>
<!-- =================================================================================== -->
<!-- |    This document was autogenerated by xacro from abb_irb2600_12_185_dual_support/urdf/abb_irb2600_dual.xacro | -->
<!-- |    EDITING THIS FILE BY HAND IS NOT RECOMMENDED                                 | -->
<!-- =================================================================================== -->
<robot name="mid_robot_dual_cell">
  <!-- Conversion were obtained from http://www.e-paint.co.uk/Lab_values.asp
       unless otherwise stated. -->
  <!-- link list -->
  <link name="base_link">
    <collision>
      <origin quat="0 0 0 1" xyz="0 0 0"/>
      <geometry>
        <mesh filename="meshes/collision/BaseLink.stl"/>
      </geometry>
    </collision>
    <visual>
      <origin quat="0 0 0 1" xyz="0 0 0"/>
      <geometry>
        <mesh filename="meshes/visual/BaseLink.stl"/>
      </geometry>
      <material name="">
        <color rgba="0.3450980 0.3647059 0.3686275 1"/>
      </material>
    </visual>
  </link>
  <link name="link_1">
    <collision>
      <origin quat="0 0 0 1" xyz="0 0 -0.445"/>
      <geometry>
        <mesh filename="meshes/collision/Link1.stl"/>
      </geometry>
    </collision>
    <visual>
      <origin quat="0 0 0 1" xyz="0 0 -0.445"/>
      <geometry>
        <mesh filename="meshes/visual/Link1.stl"/>
      </geometry>
      <material name="">
        <color rgba="0.3450980 0.3647059 0.3686275 1"/>
      </material>
    </visual>
  </link>
  <link name="link_2">
    <collision>
      <origin quat="0 0 0 1" xyz="-0.15 0 -0.445"/>
      <geometry>
        <mesh filename="meshes/collision/Link2.stl"/>
      </geometry>
    </collision>
    <visual>
      <origin quat="0 0 0 1" xyz="-0.15 0 -0.445"/>
      <geometry>
        <mesh filename="meshes/visual/Link2.stl"/>
      </geometry>
      <material name="">
        <color rgba="0.3450980 0.3647059 0.3686275 1"/>
      </material>
    </visual>
  </link>
  <link name="link_3">
    <collision>
      <origin quat="0 0 0 1" xyz="-0.15 0 -1.345"/>
      <geometry>
        <mesh filename="meshes/collision/Link3.stl"/>
      </geometry>
    </collision>
    <visual>
      <origin quat="0 0 0 1" xyz="-0.15 0 -1.345"/>
      <geometry>
        <mesh filename="meshes/visual/Link3.stl"/>
      </geometry>
      <material name="">
        <color rgba="0.3450980 0.3647059 0.3686275 1"/>
      </material>
    </visual>
  </link>
  <link name="link_4">
    <collision>
      <origin quat="0 0 0 1" xyz="-0.15 0 -1.46"/>
      <geometry>
        <mesh filename="meshes/collision/Link4.stl"/>
      </geometry>
    </collision>
    <visual>
      <origin quat="0 0 0 1" xyz="-0.15 0 -1.46"/>
      <geometry>
        <mesh filename="meshes/visual/Link4.stl"/>
      </geometry>
      <material name="">
        <color rgba="0.7725490 0.7803922 0.7686275 1"/>
      </material>
    </visual>
  </link>
  <link name="link_5">
    <collision>
      <origin quat="0 0 0 1" xyz="-0.945 0 -1.46"/>
      <geometry>
        <mesh filename="meshes/collision/Link5.stl"/>
      </geometry>
    </collision>
    <visual>
      <origin quat="0 0 0 1" xyz="-0.945 0 -1.46"/>
      <geometry>
        <mesh filename="meshes/visual/Link5.stl"/>
      </geometry>
      <material name="">
        <color rgba="0.7725490 0.7803922 0.7686275 1"/>
      </material>
    </visual>
  </link>
  <link name="link_6">
    <collision>
      <origin quat="0 0 0 1" xyz="-1.03 0 -1.46"/>
      <geometry>
        <mesh filename="meshes/collision/Link6.stl"/>
      </geometry>
    </collision>
    <visual>
      <origin quat="0 0 0 1" xyz="-1.03 0 -1.46"/>
      <geometry>
        <mesh filename="meshes/visual/Link6.stl"/>
      </geometry>
      <material name="">
        <color rgba="0.8392157 0.8352941 0.7921569 1"/>
      </material>
    </visual>
  </link>
  <!-- end of link list -->
  <!-- joint list -->
  <joint name="joint_1" type="revolute">
    <origin quat="0 0 0 1" xyz="0.000 0.000 0.445"/>
    <axis xyz="0 0 1"/>
    <parent link="base_link"/>
    <child link="link_1"/>
    <limit acceleration="15.27" effort="0.0" lower="-3.1215" upper="3.12159" velocity="3.054"/>
  </joint>
  <joint name="joint_2" type="revolute">
    <origin quat="0 0 0 1" xyz="0.150 0.000 0.000"/>
    <axis xyz="0 1 0"/>
    <parent link="link_1"/>
    <child link="link_2"/>
    <limit acceleration="15.27" effort="0.0" lower="-1.638" upper="2.685" velocity="3.054"/>
  </joint>
  <joint name="joint_3" type="revolute">
    <origin quat="0 0 0 1" xyz="0.000 0.000 0.900"/>
    <axis xyz="0 1 0"/>
    <parent link="link_2"/>
    <child link="link_3"/>
    <limit acceleration="15.27" effort="0.0" lower="-3.12159" upper="1.289" velocity="3.054"/>
  </joint>
  <joint name="joint_4" type="revolute">
    <origin quat="0 0 0 1" xyz="0.000 0.000 0.115"/>
    <axis xyz="1 0 0"/>
    <parent link="link_3"/>
    <child link="link_4"/>
    <limit acceleration="31.4150" effort="0.0" lower="-6.961" upper="6.961" velocity="6.283"/>
  </joint>
  <joint name="joint_5" type="revolute">
    <origin quat="0 0 0 1" xyz="0.795 0.000 0.000"/>
    <axis xyz="0 1 0"/>
    <parent link="link_4"/>
    <child link="link_5"/>
    <limit acceleration="31.4150" effort="0.0" lower="-2.074" upper="2.074" velocity="6.283"/>
  </joint>
  <joint name="joint_6" type="revolute">
    <origin quat="0 0 0 1" xyz="0.085 0.000 0.000"/>
    <axis xyz="1 0 0"/>
    <parent link="link_5"/>
    <child link="link_6"/>
    <limit acceleration="43.6350" effort="0.0" lower="-6.961" upper="6.961" velocity="8.727"/>
  </joint>
  <!-- end of joint list -->
  <!-- ROS-Industrial 'base' frame: base_link to ABB World Coordinates transform -->
  <link name="base"/>
  <joint name="base_link-base" type="fixed">
    <origin rpy="0 0 0" xyz="0 0 0"/>
    <parent link="base_link"/>
    <child link="base"/>
  </joint>
  <!-- ROS-Industrial 'flange' frame: attachment point for EEF models -->
  <link name="flange">
  <collision>
      <origin quat="0 0 0 1" xyz="0 0 0"/>
      <geometry>
        <mesh filename="meshes/collision/tool.stl"/>
      </geometry>
    </collision>
    <visual>
      <origin quat="0 0 0 1" xyz="0 0 0"/>
      <geometry>
        <mesh filename="meshes/visual/tool.stl"/>
      </geometry>
      <material name="">
        <color rgba="0.7725490 0.7803922 0.7686275 1"/>
      </material>
    </visual>
   </link>
  <joint name="joint_6-flange" type="fixed">
    <origin rpy="0 0 0" xyz="0 0 0"/>
    <parent link="link_6"/>
    <child link="flange"/>
  </joint>
  <!-- ROS-Industrial 'tool0' frame: all-zeros tool frame -->
  <link name="tool0" />
  <joint name="flange-tool0" type="fixed">
    <origin rpy="0 1.5707963267948966 0" xyz="0 0 0"/>
    <parent link="flange"/>
    <child link="tool0"/>
  </joint>
  <link name="world"/>
  <joint name="joint" type="fixed">
    <parent link="world"/>
    <child link="base_link"/>
    <origin rpy="0.0 0 0" xyz="0.0 0 0"/>
  </joint>
</robot>
